<?xml version="1.0"?>
<robot name="three_link_arm">

  <!-- Fixed base -->
  <link name="base_link">
    <visual>
      <geometry><cylinder length="0.05" radius="0.06"/></geometry>
      <material name="grey"><color rgba="0.5 0.5 0.5 1"/></material>
    </visual>
    <collision>
      <geometry><cylinder length="0.05" radius="0.06"/></geometry>
    </collision>
    <inertial>
      <mass value="1.0"/>
      <inertia ixx="0.001" ixy="0" ixz="0" iyy="0.001" iyz="0" izz="0.001"/>
    </inertial>
  </link>

  <!-- Joint 0: base rotation (yaw around Z) -->
  <joint name="joint_0" type="revolute">
    <parent link="base_link"/>
    <child link="link_1"/>
    <origin xyz="0 0 0.025" rpy="0 0 0"/>
    <axis xyz="0 0 1"/>
    <limit lower="-3.14" upper="3.14" effort="100" velocity="2.0"/>
  </joint>

  <!-- Link 1: short vertical connector -->
  <link name="link_1">
    <visual>
      <origin xyz="0 0 0.05"/>
      <geometry><cylinder length="0.1" radius="0.04"/></geometry>
      <material name="blue"><color rgba="0.2 0.4 0.8 1"/></material>
    </visual>
    <collision>
      <origin xyz="0 0 0.05"/>
      <geometry><cylinder length="0.1" radius="0.04"/></geometry>
    </collision>
    <inertial>
      <mass value="0.5"/>
      <origin xyz="0 0 0.05"/>
      <inertia ixx="0.001" ixy="0" ixz="0" iyy="0.001" iyz="0" izz="0.001"/>
    </inertial>
  </link>

  <!-- Joint 1: shoulder pitch (around Y) -->
  <joint name="joint_1" type="revolute">
    <parent link="link_1"/>
    <child link="link_2"/>
    <origin xyz="0 0 0.1" rpy="0 0 0"/>
    <axis xyz="0 1 0"/>
    <limit lower="-1.047" upper="1.047" effort="100" velocity="2.0"/>
  </joint>

  <!-- Link 2: upper arm -->
  <link name="link_2">
    <visual>
      <origin xyz="0 0 0.15"/>
      <geometry><cylinder length="0.3" radius="0.03"/></geometry>
      <material name="green"><color rgba="0.2 0.8 0.4 1"/></material>
    </visual>
    <collision>
      <origin xyz="0 0 0.15"/>
      <geometry><cylinder length="0.3" radius="0.03"/></geometry>
    </collision>
    <inertial>
      <mass value="0.3"/>
      <origin xyz="0 0 0.15"/>
      <inertia ixx="0.001" ixy="0" ixz="0" iyy="0.001" iyz="0" izz="0.001"/>
    </inertial>
  </link>

  <!-- Joint 2: elbow pitch (around Y) -->
  <joint name="joint_2" type="revolute">
    <parent link="link_2"/>
    <child link="link_3"/>
    <origin xyz="0 0 0.3" rpy="0 0 0"/>
    <axis xyz="0 1 0"/>
    <limit lower="-2.35" upper="2.35" effort="100" velocity="2.0"/>
  </joint>

  <!-- Link 3: forearm + end-effector -->
  <link name="link_3">
    <visual>
      <origin xyz="0 0 0.15"/>
      <geometry><cylinder length="0.3" radius="0.025"/></geometry>
      <material name="red"><color rgba="0.8 0.2 0.2 1"/></material>
    </visual>
    <collision>
      <origin xyz="0 0 0.15"/>
      <geometry><cylinder length="0.3" radius="0.025"/></geometry>
    </collision>
    <inertial>
      <mass value="0.2"/>
      <origin xyz="0 0 0.15"/>
      <inertia ixx="0.0005" ixy="0" ixz="0" iyy="0.0005" iyz="0" izz="0.0005"/>
    </inertial>
  </link>

  <!-- End-effector (tip) -->
  <joint name="ee_joint" type="fixed">
    <parent link="link_3"/>
    <child link="ee_link"/>
    <origin xyz="0 0 0.3" rpy="0 0 0"/>
  </joint>

  <link name="ee_link">
    <visual>
      <geometry><sphere radius="0.02"/></geometry>
      <material name="yellow"><color rgba="1.0 0.9 0.0 1"/></material>
    </visual>
    <inertial>
      <mass value="0.01"/>
      <inertia ixx="0.00001" ixy="0" ixz="0" iyy="0.00001" iyz="0" izz="0.00001"/>
    </inertial>
  </link>

</robot>
